<mujoco model="two_link_arm">
  <worldbody>
    <body name="link1" pos="0 0 0.1">
      <geom type="capsule" fromto="0 0 0 0 0 0.6" size="0.05" rgba="0.2 0.6 0.8 1"/>
      <joint name="joint1" type="hinge" axis="0 1 0" pos="0 0 0"/>
      
      <body name="link2" pos="0 0 0.6">
        <geom type="capsule" fromto="0 0 0 0 0 0.6" size="0.05" rgba="0.8 0.4 0.2 1"/>
        <joint name="joint2" type="hinge" axis="0 1 0" pos="0 0 0"/>
      </body>
    </body>
  </worldbody>

  <actuator>
    <position joint="joint1" ctrlrange="-1.0 1.0" gear="100"/>
    <position joint="joint2" ctrlrange="-1.0 1.0" gear="100"/>
  </actuator>

</mujoco>